Workbook

Sheet Quick Setup
A1: Rounding | C1: Make a copy (for google drive; recommended) or download this spreadsheet (for other spreadsheet programs). Do not request editing access
A2: 2.5
C4: Main Lifts | D4: Maxes | E4: Single @8 percentage | I4: When above or below RIR target
C5: Squat | D5: 110 | E5: 0.9 | H5: Sets | I5: 2+ fewer sets completed | J5: 1 fewer set completed or last set below RIR target | K5: Set target completed; last at RIR target | L5: 1 above RIR target | M5: 2 above RIR target | N5: 3 above RIR target | O5: 4 above RIR target | P5: 5 above RIR target
C6: Bench Press | D6: 105 | E6: 0.9 | G6: =C5 -> Squat | H6: 5 | I6: -0.05 | J6: -0.02 | K6: 0 | L6: 0.005 | M6: 0.01 | N6: 0.015 | O6: 0.02 | P6: 0.03
B7: Primary stance | C7: Deadlift | D7: 140 | E7: 0.9 | G7: =C6 -> Bench Press | H7: 5 | I7: -0.05 | J7: -0.02 | K7: 0 | L7: 0.005 | M7: 0.01 | N7: 0.015 | O7: 0.02 | P7: 0.03
C8: OHP | D8: 50 | E8: 0.9 | G8: =C7 -> Deadlift | H8: 5 | I8: -0.05 | J8: -0.02 | K8: 0 | L8: 0.005 | M8: 0.01 | N8: 0.015 | O8: 0.02 | P8: 0.03
G9: =C8 -> OHP | H9: 5 | I9: -0.05 | J9: -0.02 | K9: 0 | L9: 0.005 | M9: 0.01 | N9: 0.015 | O9: 0.02 | P9: 0.03
C10: Variations: Note - if you don't know your max, you can estimate it. When in doubt, estimate low to start with | D10: Maxes | G10: =C11 -> Leg Press | H10: 5 | I10: -0.05 | J10: -0.02 | K10: 0 | L10: 0.005 | M10: 0.01 | N10: 0.015 | O10: 0.02 | P10: 0.03
B11: Squat auxiliary 1 | C11: Leg Press | D11: 250 | E11: 0.9 | G11: =C12 -> Leg Press | H11: 5 | I11: -0.05 | J11: -0.02 | K11: 0 | L11: 0.005 | M11: 0.01 | N11: 0.015 | O11: 0.02 | P11: 0.03
B12: Squat auxiliary 2 | C12: Leg Press | D12: 250 | E12: 0.9 | G12: =C13 -> Incline Press | H12: 5 | I12: -0.05 | J12: -0.02 | K12: 0 | L12: 0.005 | M12: 0.01 | N12: 0.015 | O12: 0.02 | P12: 0.03
B13: Bench auxiliary 1 | C13: Incline Press | D13: 92 | E13: 0.9 | G13: =C14 -> DB Bench | H13: 5 | I13: -0.05 | J13: -0.02 | K13: 0 | L13: 0.005 | M13: 0.01 | N13: 0.015 | O13: 0.02 | P13: 0.03
B14: Bench auxiliary 2 | C14: DB Bench | D14: 30 | E14: 0.9 | G14: =C15 -> Romanian Deadlift | H14: 5 | I14: -0.05 | J14: -0.02 | K14: 0 | L14: 0.005 | M14: 0.01 | N14: 0.015 | O14: 0.02 | P14: 0.03
B15: Deadlift auxiliary | C15: Romanian Deadlift | D15: 120 | E15: 0.9 | G15: =C16 -> DB OHP | H15: 5 | I15: -0.05 | J15: -0.02 | K15: 0 | L15: 0.005 | M15: 0.01 | N15: 0.015 | O15: 0.02 | P15: 0.03
B16: OHP auxiliary | C16: DB OHP | D16: 30 | E16: 0.9
B18: Back exercises
B19: Barbell rows
B20: DB rows
B21: Chest supported rows
B22: T-bar rows
B23: Pull-ups
B24: Chin-ups
B25: Neutral grip pull-ups
B26: Pull-downs
C30: Rep target
C31: 0.5 | D31: 0.525 | E31: 0.55 | F31: 0.575 | G31: 0.6 | H31: 0.625 | I31: 0.65 | J31: 0.675 | K31: 0.7 | L31: 0.725 | M31: 0.75 | N31: 0.775 | O31: 0.8 | P31: 0.825 | Q31: 0.85 | R31: 0.875 | S31: 0.9 | T31: 0.925 | U31: 0.95 | V31: 0.975 | W31: 1
B32: ='Quick Setup'!C5 -> Squat | C32: 8 | D32: 8 | E32: 8 | F32: 8 | G32: 7 | H32: 7 | I32: 6 | J32: 6 | K32: 5 | L32: 5 | M32: 4 | N32: 4 | O32: 3 | P32: 3 | Q32: 2 | R32: 2 | S32: 1 | T32: 1 | U32: 1 | V32: 1 | W32: 1
B33: ='Quick Setup'!C6 -> Bench Press | C33: 8 | D33: 8 | E33: 8 | F33: 8 | G33: 7 | H33: 7 | I33: 6 | J33: 6 | K33: 5 | L33: 5 | M33: 4 | N33: 4 | O33: 3 | P33: 3 | Q33: 2 | R33: 2 | S33: 1 | T33: 1 | U33: 1 | V33: 1 | W33: 1
B34: ='Quick Setup'!C7 -> Deadlift | C34: 8 | D34: 8 | E34: 8 | F34: 8 | G34: 7 | H34: 7 | I34: 6 | J34: 6 | K34: 5 | L34: 5 | M34: 4 | N34: 4 | O34: 3 | P34: 3 | Q34: 2 | R34: 2 | S34: 1 | T34: 1 | U34: 1 | V34: 1 | W34: 1
B35: ='Quick Setup'!C8 -> OHP | C35: 8 | D35: 8 | E35: 8 | F35: 8 | G35: 7 | H35: 7 | I35: 6 | J35: 6 | K35: 5 | L35: 5 | M35: 4 | N35: 4 | O35: 3 | P35: 3 | Q35: 2 | R35: 2 | S35: 1 | T35: 1 | U35: 1 | V35: 1 | W35: 1
B36: ='Quick Setup'!C11 -> Leg Press | C36: 8 | D36: 8 | E36: 8 | F36: 8 | G36: 7 | H36: 7 | I36: 6 | J36: 6 | K36: 5 | L36: 5 | M36: 4 | N36: 4 | O36: 3 | P36: 3 | Q36: 2 | R36: 2 | S36: 1 | T36: 1 | U36: 1 | V36: 1 | W36: 1
B37: ='Quick Setup'!C12 -> Leg Press | C37: 8 | D37: 8 | E37: 8 | F37: 8 | G37: 7 | H37: 7 | I37: 6 | J37: 6 | K37: 5 | L37: 5 | M37: 4 | N37: 4 | O37: 3 | P37: 3 | Q37: 2 | R37: 2 | S37: 1 | T37: 1 | U37: 1 | V37: 1 | W37: 1
B38: ='Quick Setup'!C13 -> Incline Press | C38: 8 | D38: 8 | E38: 8 | F38: 8 | G38: 7 | H38: 7 | I38: 6 | J38: 6 | K38: 5 | L38: 5 | M38: 4 | N38: 4 | O38: 3 | P38: 3 | Q38: 2 | R38: 2 | S38: 1 | T38: 1 | U38: 1 | V38: 1 | W38: 1
B39: ='Quick Setup'!C14 -> DB Bench | C39: 8 | D39: 8 | E39: 8 | F39: 8 | G39: 7 | H39: 7 | I39: 6 | J39: 6 | K39: 5 | L39: 5 | M39: 4 | N39: 4 | O39: 3 | P39: 3 | Q39: 2 | R39: 2 | S39: 1 | T39: 1 | U39: 1 | V39: 1 | W39: 1
B40: ='Quick Setup'!C15 -> Romanian Deadlift | C40: 8 | D40: 8 | E40: 8 | F40: 8 | G40: 7 | H40: 7 | I40: 6 | J40: 6 | K40: 5 | L40: 5 | M40: 4 | N40: 4 | O40: 3 | P40: 3 | Q40: 2 | R40: 2 | S40: 1 | T40: 1 | U40: 1 | V40: 1 | W40: 1
B41: ='Quick Setup'!C16 -> DB OHP | C41: 8 | D41: 8 | E41: 8 | F41: 8 | G41: 7 | H41: 7 | I41: 6 | J41: 6 | K41: 5 | L41: 5 | M41: 4 | N41: 4 | O41: 3 | P41: 3 | Q41: 2 | R41: 2 | S41: 1 | T41: 1 | U41: 1 | V41: 1 | W41: 1
C44: Last set RIR target
C45: 0.5 | D45: 0.525 | E45: 0.55 | F45: 0.575 | G45: 0.6 | H45: 0.625 | I45: 0.65 | J45: 0.675 | K45: 0.7 | L45: 0.725 | M45: 0.75 | N45: 0.775 | O45: 0.8 | P45: 0.825 | Q45: 0.85 | R45: 0.875 | S45: 0.9 | T45: 0.925 | U45: 0.95 | V45: 0.975 | W45: 1
B46: ='Quick Setup'!C5 -> Squat | C46: 3 | D46: 3 | E46: 3 | F46: 3 | G46: 3 | H46: 3 | I46: 3 | J46: 3 | K46: 3 | L46: 3 | M46: 2 | N46: 2 | O46: 2 | P46: 2 | Q46: 1 | R46: 1 | S46: 1 | T46: 1 | U46: 1 | V46: 0 | W46: 0
B47: ='Quick Setup'!C6 -> Bench Press | C47: 3 | D47: 3 | E47: 3 | F47: 3 | G47: 3 | H47: 3 | I47: 3 | J47: 3 | K47: 3 | L47: 3 | M47: 2 | N47: 2 | O47: 2 | P47: 2 | Q47: 1 | R47: 1 | S47: 1 | T47: 1 | U47: 1 | V47: 0 | W47: 0
...

Sheet Setup
A1: Week | B1: 1 | N1: =B1+1 -> 2 | Z1: =N1+1 -> 3 | AL1: =Z1+1 -> 4 | AX1: =AL1+1 -> 5 | BJ1: =AX1+1 -> 6 | BV1: =BJ1+1 -> 7 | CH1: =BV1+1 -> 8 | CT1: =CH1+1 -> 9 | DF1: =CT1+1 -> 10 | DR1: =DF1+1 -> 11 | ED1: =DR1+1 -> 12 | EP1: =ED1+1 -> 13 | FB1: =EP1+1 -> 14 | FN1: =FB1+1 -> 15 | FZ1: =FN1+1 -> 16 | GL1: =FZ1+1 -> 17 | GX1: =GL1+1 -> 18 | HJ1: =GX1+1 -> 19 | HV1: =HJ1+1 -> 20 | IH1: =HV1+1 -> 21
A2: Lift | B2: Intensity | C2: Reps per set | D2: Last set RIR | E2: Sets | F2: 2+ fewer sets completed | G2: 1 fewer set completed | H2: Set target completed; last at RIR target | I2: 1 above RIR target | J2: 2 above RIR target | K2: 3 above RIR target | L2: 4 above RIR target | M2: 5 above RIR target | N2: Intensity | O2: Reps per set | P2: Last set RIR | Q2: Sets | R2: 2+ fewer sets completed | S2: 1 fewer set completed | T2: Set target completed; last at RIR target | U2: 1 above RIR target | V2: 2 above RIR target | W2: 3 above RIR target | X2: 4 above RIR target | Y2: 5 above RIR target | Z2: Intensity | AA2: Reps per set | AB2: Last set RIR | AC2: Sets | AD2: 2+ fewer sets completed | AE2: 1 fewer set completed | AF2: Set target completed; last at RIR target | AG2: 1 above RIR target | AH2: 2 above RIR target | AI2: 3 above RIR target | AJ2: 4 above RIR target | AK2: 5 above RIR target | AL2: Intensity | AM2: Reps per set | AN2: Last set RIR | AO2: Sets | AP2: 2+ fewer sets completed | AQ2: 1 fewer set completed | AR2: Set target completed; last at RIR target | AS2: 1 above RIR target | AT2: 2 above RIR target | AU2: 3 above RIR target | AV2: 4 above RIR target | AW2: 5 above RIR target | AX2: Intensity | AY2: Reps per set | AZ2: Last set RIR | BA2: Sets | BB2: 2+ fewer sets completed | BC2: 1 fewer set completed | BD2: Set target completed; last at RIR target | BE2: 1 above RIR target | BF2: 2 above RIR target | BG2: 3 above RIR target | BH2: 4 above RIR target | BI2: 5 above RIR target | BJ2: Intensity | BK2: Reps per set | BL2: Last set RIR | BM2: Sets | BN2: 2+ fewer sets completed | BO2: 1 fewer set completed | BP2: Set target completed; last at RIR target | BQ2: 1 above RIR target | BR2: 2 above RIR target | BS2: 3 above RIR target | BT2: 4 above RIR target | BU2: 5 above RIR target | BV2: Intensity | BW2: Reps per set | BX2: Last set RIR | BY2: Sets | BZ2: 2+ fewer sets completed | CA2: 1 fewer set completed | CB2: Set target completed; last at RIR target | CC2: 1 above RIR target | CD2: 2 above RIR target | CE2: 3 above RIR target | CF2: 4 above RIR target | CG2: 5 above RIR target | CH2: Intensity | CI2: Reps per set | CJ2: Last set RIR | CK2: Sets | CL2: 2+ fewer sets completed | CM2: 1 fewer set completed | CN2: Set target completed; last at RIR target | CO2: 1 above RIR target | CP2: 2 above RIR target | CQ2: 3 above RIR target | CR2: 4 above RIR target | CS2: 5 above RIR target | CT2: Intensity | CU2: Reps per set | CV2: Last set RIR | CW2: Sets | CX2: 2+ fewer sets completed | CY2: 1 fewer set completed | CZ2: Set target completed; last at RIR target | DA2: 1 above RIR target | DB2: 2 above RIR target | DC2: 3 above RIR target | DD2: 4 above RIR target | DE2: 5 above RIR target | DF2: Intensity | DG2: Reps per set | DH2: Last set RIR | DI2: Sets | DJ2: 2+ fewer sets completed | DK2: 1 fewer set completed | DL2: Set target completed; last at RIR target | DM2: 1 above RIR target | DN2: 2 above RIR target | DO2: 3 above RIR target | DP2: 4 above RIR target | DQ2: 5 above RIR target | DR2: Intensity | DS2: Reps per set | DT2: Last set RIR | DU2: Sets | DV2: 2+ fewer sets completed | DW2: 1 fewer set completed | DX2: Set target completed; last at RIR target | DY2: 1 above RIR target | DZ2: 2 above RIR target | EA2: 3 above RIR target | EB2: 4 above RIR target | EC2: 5 above RIR target | ED2: Intensity | EE2: Reps per set | EF2: Last set RIR | EG2: Sets | EH2: 2+ fewer sets completed | EI2: 1 fewer set completed | EJ2: Set target completed; last at RIR target | EK2: 1 above RIR target | EL2: 2 above RIR target | EM2: 3 above RIR target | EN2: 4 above RIR target | EO2: 5 above RIR target | EP2: Intensity | EQ2: Reps per set | ER2: Last set RIR | ES2: Sets | ET2: 2+ fewer sets completed | EU2: 1 fewer set completed | EV2: Set target completed; last at RIR target | EW2: 1 above RIR target | EX2: 2 above RIR target | EY2: 3 above RIR target | EZ2: 4 above RIR target | FA2: 5 above RIR target | FB2: Intensity | FC2: Reps per set | FD2: Last set RIR | FE2: Sets | FF2: 2+ fewer sets completed | FG2: 1 fewer set completed | FH2: Set target completed; last at RIR target | FI2: 1 above RIR target | FJ2: 2 above RIR target | FK2: 3 above RIR target | FL2: 4 above RIR target | FM2: 5 above RIR target | FN2: Intensity | FO2: Reps per set | FP2: Last set RIR | FQ2: Sets | FR2: 2+ fewer sets completed | FS2: 1 fewer set completed | FT2: Set target completed; last at RIR target | FU2: 1 above RIR target | FV2: 2 above RIR target | FW2: 3 above RIR target | FX2: 4 above RIR target | FY2: 5 above RIR target | FZ2: Intensity | GA2: Reps per set | GB2: Last set RIR | GC2: Sets | GD2: 2+ fewer sets completed | GE2: 1 fewer set completed | GF2: Set target completed; last at RIR target | GG2: 1 above RIR target | GH2: 2 above RIR target | GI2: 3 above RIR target | GJ2: 4 above RIR target | GK2: 5 above RIR target | GL2: Intensity | GM2: Reps per set | GN2: Last set RIR | GO2: Sets | GP2: 2+ fewer sets completed | GQ2: 1 fewer set completed | GR2: Set target completed; last at RIR target | GS2: 1 above RIR target | GT2: 2 above RIR target | GU2: 3 above RIR target | GV2: 4 above RIR target | GW2: 5 above RIR target | GX2: Intensity | GY2: Reps per set | GZ2: Last set RIR | HA2: Sets | HB2: 2+ fewer sets completed | HC2: 1 fewer set completed | HD2: Set target completed; last at RIR target | HE2: 1 above RIR target | HF2: 2 above RIR target | HG2: 3 above RIR target | HH2: 4 above RIR target | HI2: 5 above RIR target | HJ2: Intensity | HK2: Reps per set | HL2: Last set RIR | HM2: Sets | HN2: 2+ fewer sets completed | HO2: 1 fewer set completed | HP2: Set target completed; last at RIR target | HQ2: 1 above RIR target | HR2: 2 above RIR target | HS2: 3 above RIR target | HT2: 4 above RIR target | HU2: 5 above RIR target | HV2: Intensity | HW2: Reps per set | HX2: Last set RIR | HY2: Sets | HZ2: 2+ fewer sets completed | IA2: 1 fewer set completed | IB2: Set target completed; last at RIR target | IC2: 1 above RIR target | ID2: 2 above RIR target | IE2: 3 above RIR target | IF2: 4 above RIR target | IG2: 5 above RIR target | IH2: Intensity | II2: Reps per set | IJ2: Last set RIR | IK2: Sets | IL2: 2+ fewer sets completed | IM2: 1 fewer set completed | IN2: Set target completed; last at RIR target | IO2: 1 above RIR target | IP2: 2 above RIR target | IQ2: 3 above RIR target | IR2: 4 above RIR target | IS2: 5 above RIR target
A3: ='Quick Setup'!C5 -> Squat | B3: ='Quick Setup'!C60 -> 0.7 | C3: =if(B3='Quick Setup'!$C$31,'Quick Setup'!$C32,if(B3='Quick Setup'!$D$31,'Quick Setup'!$D32,if(B3='Quick Setup'!$E$31,'Quick Setup'!$E32,if(B3='Quick Setup'!$F$31,'Quick Setup'!$F32,if(B3='Quick Setup'!$G$31,'Quick Setup'!$G32,if(B3='Quick Setup'!$H$31,'Quick Setup'!$H32,if(B3='Quick Setup'!$I$31,'Quick Setup'!$I32,if(B3='Quick Setup'!$J$31,'Quick Setup'!$J32,if(B3='Quick Setup'!$K$31,'Quick Setup'!$K32,if(B3='Quick Setup'!$L$31,'Quick Setup'!$L32,if(B3='Quick Setup'!$M$31,'Quick Setup'!$M32,if(B3='Quick Setup'!$N$31,'Quick Setup'!$N32,if(B3='Quick Setup'!$O$31,'Quick Setup'!$O32,if(B3='Quick Setup'!$P$31,'Quick Setup'!$P32,if(B3='Quick Setup'!$Q$31,'Quick Setup'!$Q32,if(B3='Quick Setup'!$R$31,'Quick Setup'!$R32,if(B3='Quick Setup'!$S$31,'Quick Setup'!$S32,if(B3='Quick Setup'!$T$31,'Quick Setup'!$T32,if(B3='Quick Setup'!$U$31,'Quick Setup'!$U32,if(B3='Quick Setup'!$V$31,'Quick Setup'!$V32,'Quick Setup'!$W32)))))))))))))))))))) -> 5 | D3: =if(B3='Quick Setup'!$C$45,'Quick Setup'!$C46,if(B3='Quick Setup'!$D$45,'Quick Setup'!$D46,if(B3='Quick Setup'!$E$45,'Quick Setup'!$E46,if(B3='Quick Setup'!$F$45,'Quick Setup'!$F46,if(B3='Quick Setup'!$G$45,'Quick Setup'!$G46,if(B3='Quick Setup'!$H$45,'Quick Setup'!$H46,if(B3='Quick Setup'!$I$45,'Quick Setup'!$I46,if(B3='Quick Setup'!$J$45,'Quick Setup'!$J46,if(B3='Quick Setup'!$K$45,'Quick Setup'!$K46,if(B3='Quick Setup'!$L$45,'Quick Setup'!$L46,if(B3='Quick Setup'!$M$45,'Quick Setup'!$M46,if(B3='Quick Setup'!$N$45,'Quick Setup'!$N46,if(B3='Quick Setup'!$O$45,'Quick Setup'!$O46,if(B3='Quick Setup'!$P$45,'Quick Setup'!$P46,if(B3='Quick Setup'!$Q$45,'Quick Setup'!$Q46,if(B3='Quick Setup'!$R$45,'Quick Setup'!$R46,if(B3='Quick Setup'!$S$45,'Quick Setup'!$S46,if(B3='Quick Setup'!$T$45,'Quick Setup'!$T46,if(B3='Quick Setup'!$U$45,'Quick Setup'!$U46,if(B3='Quick Setup'!$V$45,'Quick Setup'!$V46,'Quick Setup'!$W46)))))))))))))))))))) -> 3 | E3: ='Quick Setup'!H6 -> 5 | F3: ='Quick Setup'!I6 -> -0.05 | G3: ='Quick Setup'!J6 -> -0.02 | H3: ='Quick Setup'!K6 -> 0 | I3: ='Quick Setup'!L6 -> 0.005 | J3: ='Quick Setup'!M6 -> 0.01 | K3: ='Quick Setup'!N6 -> 0.015 | L3: ='Quick Setup'!O6 -> 0.02 | M3: ='Quick Setup'!P6 -> 0.03 | N3: ='Quick Setup'!D60 -> 0.75 | O3: =if(N3='Quick Setup'!$C$31,'Quick Setup'!$C32,if(N3='Quick Setup'!$D$31,'Quick Setup'!$D32,if(N3='Quick Setup'!$E$31,'Quick Setup'!$E32,if(N3='Quick Setup'!$F$31,'Quick Setup'!$F32,if(N3='Quick Setup'!$G$31,'Quick Setup'!$G32,if(N3='Quick Setup'!$H$31,'Quick Setup'!$H32,if(N3='Quick Setup'!$I$31,'Quick Setup'!$I32,if(N3='Quick Setup'!$J$31,'Quick Setup'!$J32,if(N3='Quick Setup'!$K$31,'Quick Setup'!$K32,if(N3='Quick Setup'!$L$31,'Quick Setup'!$L32,if(N3='Quick Setup'!$M$31,'Quick Setup'!$M32,if(N3='Quick Setup'!$N$31,'Quick Setup'!$N32,if(N3='Quick Setup'!$O$31,'Quick Setup'!$O32,if(N3='Quick Setup'!$P$31,'Quick Setup'!$P32,if(N3='Quick Setup'!$Q$31,'Quick Setup'!$Q32,if(N3='Quick Setup'!$R$31,'Quick Setup'!$R32,if(N3='Quick Setup'!$S$31,'Quick Setup'!$S32,if(N3='Quick Setup'!$T$31,'Quick Setup'!$T32,if(N3='Quick Setup'!$U$31,'Quick Setup'!$U32,if(N3='Quick Setup'!$V$31,'Quick Setup'!$V32,'Quick Setup'!$W32)))))))))))))))))))) -> 4 | P3: =if(N3='Quick Setup'!$C$45,'Quick Setup'!$C46,if(N3='Quick Setup'!$D$45,'Quick Setup'!$D46,if(N3='Quick Setup'!$E$45,'Quick Setup'!$E46,if(N3='Quick Setup'!$F$45,'Quick Setup'!$F46,if(N3='Quick Setup'!$G$45,'Quick Setup'!$G46,if(N3='Quick Setup'!$H$45,'Quick Setup'!$H46,if(N3='Quick Setup'!$I$45,'Quick Setup'!$I46,if(N3='Quick Setup'!$J$45,'Quick Setup'!$J46,if(N3='Quick Setup'!$K$45,'Quick Setup'!$K46,if(N3='Quick Setup'!$L$45,'Quick Setup'!$L46,if(N3='Quick Setup'!$M$45,'Quick Setup'!$M46,if(N3='Quick Setup'!$N$45,'Quick Setup'!$N46,if(N3='Quick Setup'!$O$45,'Quick Setup'!$O46,if(N3='Quick Setup'!$P$45,'Quick Setup'!$P46,if(N3='Quick Setup'!$Q$45,'Quick Setup'!$Q46,if(N3='Quick Setup'!$R$45,'Quick Setup'!$R46,if(N3='Quick Setup'!$S$45,'Quick Setup'!$S46,if(N3='Quick Setup'!$T$45,'Quick Setup'!$T46,if(N3='Quick Setup'!$U$45,'Quick Setup'!$U46,if(N3='Quick Setup'!$V$45,'Quick Setup'!$V46,'Quick Setup'!$W46)))))))))))))))))))) -> 2 | Q3: =E3 -> 5 | R3: =F3 -> -0.05 | S3: =G3 -> -0.02 | T3: =H3 -> 0 | U3: =I3 -> 0.005 | V3: =J3 -> 0.01 | W3: =K3 -> 0.015 | X3: =L3 -> 0.02 | Y3: =M3 -> 0.03 | Z3: ='Quick Setup'!E60 -> 0.8 | AA3: =if(Z3='Quick Setup'!$C$31,'Quick Setup'!$C32,if(Z3='Quick Setup'!$D$31,'Quick Setup'!$D32,if(Z3='Quick Setup'!$E$31,'Quick Setup'!$E32,if(Z3='Quick Setup'!$F$31,'Quick Setup'!$F32,if(Z3='Quick Setup'!$G$31,'Quick Setup'!$G32,if(Z3='Quick Setup'!$H$31,'Quick Setup'!$H32,if(Z3='Quick Setup'!$I$31,'Quick Setup'!$I32,if(Z3='Quick Setup'!$J$31,'Quick Setup'!$J32,if(Z3='Quick Setup'!$K$31,'Quick Setup'!$K32,if(Z3='Quick Setup'!$L$31,'Quick Setup'!$L32,if(Z3='Quick Setup'!$M$31,'Quick Setup'!$M32,if(Z3='Quick Setup'!$N$31,'Quick Setup'!$N32,if(Z3='Quick Setup'!$O$31,'Quick Setup'!$O32,if(Z3='Quick Setup'!$P$31,'Quick Setup'!$P32,if(Z3='Quick Setup'!$Q$31,'Quick Setup'!$Q32,if(Z3='Quick Setup'!$R$31,'Quick Setup'!$R32,if(Z3='Quick Setup'!$S$31,'Quick Setup'!$S32,if(Z3='Quick Setup'!$T$31,'Quick Setup'!$T32,if(Z3='Quick Setup'!$U$31,'Quick Setup'!$U32,if(Z3='Quick Setup'!$V$31,'Quick Setup'!$V32,'Quick Setup'!$W32)))))))))))))))))))) -> 3 | AB3: =if(Z3='Quick Setup'!$C$45,'Quick Setup'!$C46,if(Z3='Quick Setup'!$D$45,'Quick Setup'!$D46,if(Z3='Quick Setup'!$E$45,'Quick Setup'!$E46,if(Z3='Quick Setup'!$F$45,'Quick Setup'!$F46,if(Z3='Quick Setup'!$G$45,'Quick Setup'!$G46,if(Z3='Quick Setup'!$H$45,'Quick Setup'!$H46,if(Z3='Quick Setup'!$I$45,'Quick Setup'!$I46,if(Z3='Quick Setup'!$J$45,'Quick Setup'!$J46,if(Z3='Quick Setup'!$K$45,'Quick Setup'!$K46,if(Z3='Quick Setup'!$L$45,'Quick Setup'!$L46,if(Z3='Quick Setup'!$M$45,'Quick Setup'!$M46,if(Z3='Quick Setup'!$N$45,'Quick Setup'!$N46,if(Z3='Quick Setup'!$O$45,'Quick Setup'!$O46,if(Z3='Quick Setup'!$P$45,'Quick Setup'!$P46,if(Z3='Quick Setup'!$Q$45,'Quick Setup'!$Q46,if(Z3='Quick Setup'!$R$45,'Quick Setup'!$R46,if(Z3='Quick Setup'!$S$45,'Quick Setup'!$S46,if(Z3='Quick Setup'!$T$45,'Quick Setup'!$T46,if(Z3='Quick Setup'!$U$45,'Quick Setup'!$U46,if(Z3='Quick Setup'!$V$45,'Quick Setup'!$V46,'Quick Setup'!$W46)))))))))))))))))))) -> 2 | AC3: =Q3 -> 5 | AD3: =R3 -> -0.05 | AE3: =S3 -> -0.02 | AF3: =T3 -> 0 | AG3: =U3 -> 0.005 | AH3: =V3 -> 0.01 | AI3: =W3 -> 0.015 | AJ3: =X3 -> 0.02 | AK3: =Y3 -> 0.03 | AL3: ='Quick Setup'!F60 -> 0.725 | AM3: =if(AL3='Quick Setup'!$C$31,'Quick Setup'!$C32,if(AL3='Quick Setup'!$D$31,'Quick Setup'!$D32,if(AL3='Quick Setup'!$E$31,'Quick Setup'!$E32,if(AL3='Quick Setup'!$F$31,'Quick Setup'!$F32,if(AL3='Quick Setup'!$G$31,'Quick Setup'!$G32,if(AL3='Quick Setup'!$H$31,'Quick Setup'!$H32,if(AL3='Quick Setup'!$I$31,'Quick Setup'!$I32,if(AL3='Quick Setup'!$J$31,'Quick Setup'!$J32,if(AL3='Quick Setup'!$K$31,'Quick Setup'!$K32,if(AL3='Quick Setup'!$L$31,'Quick Setup'!$L32,if(AL3='Quick Setup'!$M$31,'Quick Setup'!$M32,if(AL3='Quick Setup'!$N$31,'Quick Setup'!$N32,if(AL3='Quick Setup'!$O$31,'Quick Setup'!$O32,if(AL3='Quick Setup'!$P$31,'Quick Setup'!$P32,if(AL3='Quick Setup'!$Q$31,'Quick Setup'!$Q32,if(AL3='Quick Setup'!$R$31,'Quick Setup'!$R32,if(AL3='Quick Setup'!$S$31,'Quick Setup'!$S32,if(AL3='Quick Setup'!$T$31,'Quick Setup'!$T32,if(AL3='Quick Setup'!$U$31,'Quick Setup'!$U32,if(AL3='Quick Setup'!$V$31,'Quick Setup'!$V32,'Quick Setup'!$W32)))))))))))))))))))) -> 5 | AN3: =if(AL3='Quick Setup'!$C$45,'Quick Setup'!$C46,if(AL3='Quick Setup'!$D$45,'Quick Setup'!$D46,if(AL3='Quick Setup'!$E$45,'Quick Setup'!$E46,if(AL3='Quick Setup'!$F$45,'Quick Setup'!$F46,if(AL3='Quick Setup'!$G$45,'Quick Setup'!$G46,if(AL3='Quick Setup'!$H$45,'Quick Setup'!$H46,if(AL3='Quick Setup'!$I$45,'Quick Setup'!$I46,if(AL3='Quick Setup'!$J$45,'Quick Setup'!$J46,if(AL3='Quick Setup'!$K$45,'Quick Setup'!$K46,if(AL3='Quick Setup'!$L$45,'Quick Setup'!$L46,if(AL3='Quick Setup'!$M$45,'Quick Setup'!$M46,if(AL3='Quick Setup'!$N$45,'Quick Setup'!$N46,if(AL3='Quick Setup'!$O$45,'Quick Setup'!$O46,if(AL3='Quick Setup'!$P$45,'Quick Setup'!$P46,if(AL3='Quick Setup'!$Q$45,'Quick Setup'!$Q46,if(AL3='Quick Setup'!$R$45,'Quick Setup'!$R46,if(AL3='Quick Setup'!$S$45,'Quick Setup'!$S46,if(AL3='Quick Setup'!$T$45,'Quick Setup'!$T46,if(AL3='Quick Setup'!$U$45,'Quick Setup'!$U46,if(AL3='Quick Setup'!$V$45,'Quick Setup'!$V46,'Quick Setup'!$W46)))))))))))))))))))) -> 3 | AO3: =AC3 -> 5 | AP3: =AD3 -> -0.05 | AQ3: =AE3 -> -0.02 | AR3: =AF3 -> 0 | AS3: =AG3 -> 0.005 | AT3: =AH3 -> 0.01 | AU3: =AI3 -> 0.015 | AV3: =AJ3 -> 0.02 | AW3: =AK3 -> 0.03 | AX3: ='Quick Setup'!G60 -> 0.775 | AY3: =if(AX3='Quick Setup'!$C$31,'Quick Setup'!$C32,if(AX3='Quick Setup'!$D$31,'Quick Setup'!$D32,if(AX3='Quick Setup'!$E$31,'Quick Setup'!$E32,if(AX3='Quick Setup'!$F$31,'Quick Setup'!$F32,if(AX3='Quick Setup'!$G$31,'Quick Setup'!$G32,if(AX3='Quick Setup'!$H$31,'Quick Setup'!$H32,if(AX3='Quick Setup'!$I$31,'Quick Setup'!$I32,if(AX3='Quick Setup'!$J$31,'Quick Setup'!$J32,if(AX3='Quick Setup'!$K$31,'Quick Setup'!$K32,if(AX3='Quick Setup'!$L$31,'Quick Setup'!$L32,if(AX3='Quick Setup'!$M$31,'Quick Setup'!$M32,if(AX3='Quick Setup'!$N$31,'Quick Setup'!$N32,if(AX3='Quick Setup'!$O$31,'Quick Setup'!$O32,if(AX3='Quick Setup'!$P$31,'Quick Setup'!$P32,if(AX3='Quick Setup'!$Q$31,'Quick Setup'!$Q32,if(AX3='Quick Setup'!$R$31,'Quick Setup'!$R32,if(AX3='Quick Setup'!$S$31,'Quick Setup'!$S32,if(AX3='Quick Setup'!$T$31,'Quick Setup'!$T32,if(AX3='Quick Setup'!$U$31,'Quick Setup'!$U32,if(AX3='Quick Setup'!$V$31,'Quick Setup'!$V32,'Quick Setup'!$W32)))))))))))))))))))) -> 4 | AZ3: =if(AX3='Quick Setup'!$C$45,'Quick Setup'!$C46,if(AX3='Quick Setup'!$D$45,'Quick Setup'!$D46,if(AX3='Quick Setup'!$E$45,'Quick Setup'!$E46,if(AX3='Quick Setup'!$F$45,'Quick Setup'!$F46,if(AX3='Quick Setup'!$G$45,'Quick Setup'!$G46,if(AX3='Quick Setup'!$H$45,'Quick Setup'!$H46,if(AX3='Quick Setup'!$I$45,'Quick Setup'!$I46,if(AX3='Quick Setup'!$J$45,'Quick Setup'!$J46,if(AX3='Quick Setup'!$K$45,'Quick Setup'!$K46,if(AX3='Quick Setup'!$L$45,'Quick Setup'!$L46,if(AX3='Quick Setup'!$M$45,'Quick Setup'!$M46,if(AX3='Quick Setup'!$N$45,'Quick Setup'!$N46,if(AX3='Quick Setup'!$O$45,'Quick Setup'!$O46,if(AX3='Quick Setup'!$P$45,'Quick Setup'!$P46,if(AX3='Quick Setup'!$Q$45,'Quick Setup'!$Q46,if(AX3='Quick Setup'!$R$45,'Quick Setup'!$R46,if(AX3='Quick Setup'!$S$45,'Quick Setup'!$S46,if(AX3='Quick Setup'!$T$45,'Quick Setup'!$T46,if(AX3='Quick Setup'!$U$45,'Quick Setup'!$U46,if(AX3='Quick Setup'!$V$45,'Quick Setup'!$V46,'Quick Setup'!$W46)))))))))))))))))))) -> 2 | BA3: =AO3 -> 5 | BB3: =AP3 -> -0.05 | BC3: =AQ3 -> -0.02 | BD3: =AR3 -> 0 | BE3: =AS3 -> 0.005 | BF3: =AT3 -> 0.01 | BG3: =AU3 -> 0.015 | BH3: =AV3 -> 0.02 | BI3: =AW3 -> 0.03 | BJ3: ='Quick Setup'!H60 -> 0.825 | BK3: =if(BJ3='Quick Setup'!$C$31,'Quick Setup'!$C32,if(BJ3='Quick Setup'!$D$31,'Quick Setup'!$D32,if(BJ3='Quick Setup'!$E$31,'Quick Setup'!$E32,if(BJ3='Quick Setup'!$F$31,'Quick Setup'!$F32,if(BJ3='Quick Setup'!$G$31,'Quick Setup'!$G32,if(BJ3='Quick Setup'!$H$31,'Quick Setup'!$H32,if(BJ3='Quick Setup'!$I$31,'Quick Setup'!$I32,if(BJ3='Quick Setup'!$J$31,'Quick Setup'!$J32,if(BJ3='Quick Setup'!$K$31,'Quick Setup'!$K32,if(BJ3='Quick Setup'!$L$31,'Quick Setup'!$L32,if(BJ3='Quick Setup'!$M$31,'Quick Setup'!$M32,if(BJ3='Quick Setup'!$N$31,'Quick Setup'!$N32,if(BJ3='Quick Setup'!$O$31,'Quick Setup'!$O32,if(BJ3='Quick Setup'!$P$31,'Quick Setup'!$P32,if(BJ3='Quick Setup'!$Q$31,'Quick Setup'!$Q32,if(BJ3='Quick Setup'!$R$31,'Quick Setup'!$R32,if(BJ3='Quick Setup'!$S$31,'Quick Setup'!$S32,if(BJ3='Quick Setup'!$T$31,'Quick Setup'!$T32,if(BJ3='Quick Setup'!$U$31,'Quick Setup'!$U32,if(BJ3='Quick Setup'!$V$31,'Quick Setup'!$V32,'Quick Setup'!$W32)))))))))))))))))))) -> 3 | BL3: =if(BJ3='Quick Setup'!$C$45,'Quick Setup'!$C46,if(BJ3='Quick Setup'!$D$45,'Quick Setup'!$D46,if(BJ3='Quick Setup'!$E$45,'Quick Setup'!$E46,if(BJ3='Quick Setup'!$F$45,'Quick Setup'!$F46,if(BJ3='Quick Setup'!$G$45,'Quick Setup'!$G46,if(BJ3='Quick Setup'!$H$45,'Quick Setup'!$H46,if(BJ3='Quick Setup'!$I$45,'Quick Setup'!$I46,if(BJ3='Quick Setup'!$J$45,'Quick Setup'!$J46,if(BJ3='Quick Setup'!$K$45,'Quick Setup'!$K46,if(BJ3='Quick Setup'!$L$45,'Quick Setup'!$L46,if(BJ3='Quick Setup'!$M$45,'Quick Setup'!$M46,if(BJ3='Quick Setup'!$N$45,'Quick Setup'!$N46,if(BJ3='Quick Setup'!$O$45,'Quick Setup'!$O46,if(BJ3='Quick Setup'!$P$45,'Quick Setup'!$P46,if(BJ3='Quick Setup'!$Q$45,'Quick Setup'!$Q46,if(BJ3='Quick Setup'!$R$45,'Quick Setup'!$R46,if(BJ3='Quick Setup'!$S$45,'Quick Setup'!$S46,if(BJ3='Quick Setup'!$T$45,'Quick Setup'!$T46,if(BJ3='Quick Setup'!$U$45,'Quick Setup'!$U46,if(BJ3='Quick Setup'!$V$45,'Quick Setup'!$V46,'Quick Setup'!$W46)))))))))))))))))))) -> 2 | BM3: =BA3 -> 5 | BN3: =BB3 -> -0.05 | BO3: =BC3 -> -0.02 | BP3: =BD3 -> 0 | BQ3: =BE3 -> 0.005 | BR3: =BF3 -> 0.01 | BS3: =BG3 -> 0.015 | BT3: =BH3 -> 0.02 | BU3: =BI3 -> 0.03 | BV3: ='Quick Setup'!I60 -> 0.6 | BW3: =if(BV3='Quick Setup'!$C$31,'Quick Setup'!$C32,if(BV3='Quick Setup'!$D$31,'Quick Setup'!$D32,if(BV3='Quick Setup'!$E$31,'Quick Setup'!$E32,if(BV3='Quick Setup'!$F$31,'Quick Setup'!$F32,if(BV3='Quick Setup'!$G$31,'Quick Setup'!$G32,if(BV3='Quick Setup'!$H$31,'Quick Setup'!$H32,if(BV3='Quick Setup'!$I$31,'Quick Setup'!$I32,if(BV3='Quick Setup'!$J$31,'Quick Setup'!$J32,if(BV3='Quick Setup'!$K$31,'Quick Setup'!$K32,if(BV3='Quick Setup'!$L$31,'Quick Setup'!$L32,if(BV3='Quick Setup'!$M$31,'Quick Setup'!$M32,if(BV3='Quick Setup'!$N$31,'Quick Setup'!$N32,if(BV3='Quick Setup'!$O$31,'Quick Setup'!$O32,if(BV3='Quick Setup'!$P$31,'Quick Setup'!$P32,if(BV3='Quick Setup'!$Q$31,'Quick Setup'!$Q32,if(BV3='Quick Setup'!$R$31,'Quick Setup'!$R32,if(BV3='Quick Setup'!$S$31,'Quick Setup'!$S32,if(BV3='Quick Setup'!$T$31,'Quick Setup'!$T32,if(BV3='Quick Setup'!$U$31,'Quick Setup'!$U32,if(BV3='Quick Setup'!$V$31,'Quick Setup'!$V32,'Quick Setup'!$W32)))))))))))))))))))) -> 7 | BX3: =if(BV3='Quick Setup'!$C$45,'Quick Setup'!$C46,if(BV3='Quick Setup'!$D$45,'Quick Setup'!$D46,if(BV3='Quick Setup'!$E$45,'Quick Setup'!$E46,if(BV3='Quick Setup'!$F$45,'Quick Setup'!$F46,if(BV3='Quick Setup'!$G$45,'Quick Setup'!$G46,if(BV3='Quick Setup'!$H$45,'Quick Setup'!$H46,if(BV3='Quick Setup'!$I$45,'Quick Setup'!$I46,if(BV3='Quick Setup'!$J$45,'Quick Setup'!$J46,if(BV3='Quick Setup'!$K$45,'Quick Setup'!$K46,if(BV3='Quick Setup'!$L$45,'Quick Setup'!$L46,if(BV3='Quick Setup'!$M$45,'Quick Setup'!$M46,if(BV3='Quick Setup'!$N$45,'Quick Setup'!$N46,if(BV3='Quick Setup'!$O$45,'Quick Setup'!$O46,if(BV3='Quick Setup'!$P$45,'Quick Setup'!$P46,if(BV3='Quick Setup'!$Q$45,'Quick Setup'!$Q46,if(BV3='Quick Setup'!$R$45,'Quick Setup'!$R46,if(BV3='Quick Setup'!$S$45,'Quick Setup'!$S46,if(BV3='Quick Setup'!$T$45,'Quick Setup'!$T46,if(BV3='Quick Setup'!$U$45,'Quick Setup'!$U46,if(BV3='Quick Setup'!$V$45,'Quick Setup'!$V46,'Quick Setup'!$W46)))))))))))))))))))) -> 3 | BY3: =BM3 -> 5 | BZ3: =BN3 -> -0.05 | CA3: =BO3 -> -0.02 | CB3: =BP3 -> 0 | CC3: =BQ3 -> 0.005 | CD3: =BR3 -> 0.01 | CE3: =BS3 -> 0.015 | CF3: =BT3 -> 0.02 | CG3: =BU3 -> 0.03 | CH3: ='Quick Setup'!J60 -> 0.75 | CI3: =if(CH3='Quick Setup'!$C$31,'Quick Setup'!$C32,if(CH3='Quick Setup'!$D$31,'Quick Setup'!$D32,if(CH3='Quick Setup'!$E$31,'Quick Setup'!$E32,if(CH3='Quick Setup'!$F$31,'Quick Setup'!$F32,if(CH3='Quick Setup'!$G$31,'Quick Setup'!$G32,if(CH3='Quick Setup'!$H$31,'Quick Setup'!$H32,if(CH3='Quick Setup'!$I$31,'Quick Setup'!$I32,if(CH3='Quick Setup'!$J$31,'Quick Setup'!$J32,if(CH3='Quick Setup'!$K$31,'Quick Setup'!$K32,if(CH3='Quick Setup'!$L$31,'Quick Setup'!$L32,if(CH3='Quick Setup'!$M$31,'Quick Setup'!$M32,if(CH3='Quick Setup'!$N$31,'Quick Setup'!$N32,if(CH3='Quick Setup'!$O$31,'Quick Setup'!$O32,if(CH3='Quick Setup'!$P$31,'Quick Setup'!$P32,if(CH3='Quick Setup'!$Q$31,'Quick Setup'!$Q32,if(CH3='Quick Setup'!$R$31,'Quick Setup'!$R32,if(CH3='Quick Setup'!$S$31,'Quick Setup'!$S32,if(CH3='Quick Setup'!$T$31,'Quick Setup'!$T32,if(CH3='Quick Setup'!$U$31,'Quick Setup'!$U32,if(CH3='Quick Setup'!$V$31,'Quick Setup'!$V32,'Quick Setup'!$W32)))))))))))))))))))) -> 4 | CJ3: =if(CH3='Quick Setup'!$C$45,'Quick Setup'!$C46,if(CH3='Quick Setup'!$D$45,'Quick Setup'!$D46,if(CH3='Quick Setup'!$E$45,'Quick Setup'!$E46,if(CH3='Quick Setup'!$F$45,'Quick Setup'!$F46,if(CH3='Quick Setup'!$G$45,'Quick Setup'!$G46,if(CH3='Quick Setup'!$H$45,'Quick Setup'!$H46,if(CH3='Quick Setup'!$I$45,'Quick Setup'!$I46,if(CH3='Quick Setup'!$J$45,'Quick Setup'!$J46,if(CH3='Quick Setup'!$K$45,'Quick Setup'!$K46,if(CH3='Quick Setup'!$L$45,'Quick Setup'!$L46,if(CH3='Quick Setup'!$M$45,'Quick Setup'!$M46,if(CH3='Quick Setup'!$N$45,'Quick Setup'!$N46,if(CH3='Quick Setup'!$O$45,'Quick Setup'!$O46,if(CH3='Quick Setup'!$P$45,'Quick Setup'!$P46,if(CH3='Quick Setup'!$Q$45,'Quick Setup'!$Q46,if(CH3='Quick Setup'!$R$45,'Quick Setup'!$R46,if(CH3='Quick Setup'!$S$45,'Quick Setup'!$S46,if(CH3='Quick Setup'!$T$45,'Quick Setup'!$T46,if(CH3='Quick Setup'!$U$45,'Quick Setup'!$U46,if(CH3='Quick Setup'!$V$45,'Quick Setup'!$V46,'Quick Setup'!$W46)))))))))))))))))))) -> 2 | CK3: =BY3 -> 5 | CL3: =BZ3 -> -0.05 | CM3: =CA3 -> -0.02 | CN3: =CB3 -> 0 | CO3: =CC3 -> 0.005 | CP3: =CD3 -> 0.01 | CQ3: =CE3 -> 0.015 | CR3: =CF3 -> 0.02 | CS3: =CG3 -> 0.03 | CT3: ='Quick Setup'!K60 -> 0.8 | CU3: =if(CT3='Quick Setup'!$C$31,'Quick Setup'!$C32,if(CT3='Quick Setup'!$D$31,'Quick Setup'!$D32,if(CT3='Quick Setup'!$E$31,'Quick Setup'!$E32,if(CT3='Quick Setup'!$F$31,'Quick Setup'!$F32,if(CT3='Quick Setup'!$G$31,'Quick Setup'!$G32,if(CT3='Quick Setup'!$H$31,'Quick Setup'!$H32,if(CT3='Quick Setup'!$I$31,'Quick Setup'!$I32,if(CT3='Quick Setup'!$J$31,'Quick Setup'!$J32,if(CT3='Quick Setup'!$K$31,'Quick Setup'!$K32,if(CT3='Quick Setup'!$L$31,'Quick Setup'!$L32,if(CT3='Quick Setup'!$M$31,'Quick Setup'!$M32,if(CT3='Quick Setup'!$N$31,'Quick Setup'!$N32,if(CT3='Quick Setup'!$O$31,'Quick Setup'!$O32,if(CT3='Quick Setup'!$P$31,'Quick Setup'!$P32,if(CT3='Quick Setup'!$Q$31,'Quick Setup'!$Q32,if(CT3='Quick Setup'!$R$31,'Quick Setup'!$R32,if(CT3='Quick Setup'!$S$31,'Quick Setup'!$S32,if(CT3='Quick Setup'!$T$31,'Quick Setup'!$T32,if(CT3='Quick Setup'!$U$31,'Quick Setup'!$U32,if(CT3='Quick Setup'!$V$31,'Quick Setup'!$V32,'Quick Setup'!$W32)))))))))))))))))))) -> 3 | CV3: =if(CT3='Quick Setup'!$C$45,'Quick Setup'!$C46,if(CT3='Quick Setup'!$D$45,'Quick Setup'!$D46,if(CT3='Quick Setup'!$E$45,'Quick Setup'!$E46,if(CT3='Quick Setup'!$F$45,'Quick Setup'!$F46,if(CT3='Quick Setup'!$G$45,'Quick Setup'!$G46,if(CT3='Quick Setup'!$H$45,'Quick Setup'!$H46,if(CT3='Quick Setup'!$I$45,'Quick Setup'!$I46,if(CT3='Quick Setup'!$J$45,'Quick Setup'!$J46,if(CT3='Quick Setup'!$K$45,'Quick Setup'!$K46,if(CT3='Quick Setup'!$L$45,'Quick Setup'!$L46,if(CT3='Quick Setup'!$M$45,'Quick Setup'!$M46,if(CT3='Quick Setup'!$N$45,'Quick Setup'!$N46,if(CT3='Quick Setup'!$O$45,'Quick Setup'!$O46,if(CT3='Quick Setup'!$P$45,'Quick Setup'!$P46,if(CT3='Quick Setup'!$Q$45,'Quick Setup'!$Q46,if(CT3='Quick Setup'!$R$45,'Quick Setup'!$R46,if(CT3='Quick Setup'!$S$45,'Quick Setup'!$S46,if(CT3='Quick Setup'!$T$45,'Quick Setup'!$T46,if(CT3='Quick Setup'!$U$45,'Quick Setup'!$U46,if(CT3='Quick Setup'!$V$45,'Quick Setup'!$V46,'Quick Setup'!$W46)))))))))))))))))))) -> 2 | CW3: =CK3 -> 5 | CX3: =CL3 -> -0.05 | CY3: =CM3 -> -0.02 | CZ3: =CN3 -> 0 | DA3: =CO3 -> 0.005 | DB3: =CP3 -> 0.01 | DC3: =CQ3 -> 0.015 | DD3: =CR3 -> 0.02 | DE3: =CS3 -> 0.03 | DF3: ='Quick Setup'!L60 -> 0.85 | DG3: =if(DF3='Quick Setup'!$C$31,'Quick Setup'!$C32,if(DF3='Quick Setup'!$D$31,'Quick Setup'!$D32,if(DF3='Quick Setup'!$E$31,'Quick Setup'!$E32,if(DF3='Quick Setup'!$F$31,'Quick Setup'!$F32,if(DF3='Quick Setup'!$G$31,'Quick Setup'!$G32,if(DF3='Quick Setup'!$H$31,'Quick Setup'!$H32,if(DF3='Quick Setup'!$I$31,'Quick Setup'!$I32,if(DF3='Quick Setup'!$J$31,'Quick Setup'!$J32,if(DF3='Quick Setup'!$K$31,'Quick Setup'!$K32,if(DF3='Quick Setup'!$L$31,'Quick Setup'!$L32,if(DF3='Quick Setup'!$M$31,'Quick Setup'!$M32,if(DF3='Quick Setup'!$N$31,'Quick Setup'!$N32,if(DF3='Quick Setup'!$O$31,'Quick Setup'!$O32,if(DF3='Quick Setup'!$P$31,'Quick Setup'!$P32,if(DF3='Quick Setup'!$Q$31,'Quick Setup'!$Q32,if(DF3='Quick Setup'!$R$31,'Quick Setup'!$R32,if(DF3='Quick Setup'!$S$31,'Quick Setup'!$S32,if(DF3='Quick Setup'!$T$31,'Quick Setup'!$T32,if(DF3='Quick Setup'!$U$31,'Quick Setup'!$U32,if(DF3='Quick Setup'!$V$31,'Quick Setup'!$V32,'Quick Setup'!$W32)))))))))))))))))))) -> 2 | DH3: =if(DF3='Quick Setup'!$C$45,'Quick Setup'!$C46,if(DF3='Quick Setup'!$D$45,'Quick Setup'!$D46,if(DF3='Quick Setup'!$E$45,'Quick Setup'!$E46,if(DF3='Quick Setup'!$F$45,'Quick Setup'!$F46,if(DF3='Quick Setup'!$G$45,'Quick Setup'!$G46,if(DF3='Quick Setup'!$H$45,'Quick Setup'!$H46,if(DF3='Quick Setup'!$I$45,'Quick Setup'!$I46,if(DF3='Quick Setup'!$J$45,'Quick Setup'!$J46,if(DF3='Quick Setup'!$K$45,'Quick Setup'!$K46,if(DF3='Quick Setup'!$L$45,'Quick Setup'!$L46,if(DF3='Quick Setup'!$M$45,'Quick Setup'!$M46,if(DF3='Quick Setup'!$N$45,'Quick Setup'!$N46,if(DF3='Quick Setup'!$O$45,'Quick Setup'!$O46,if(DF3='Quick Setup'!$P$45,'Quick Setup'!$P46,if(DF3='Quick Setup'!$Q$45,'Quick Setup'!$Q46,if(DF3='Quick Setup'!$R$45,'Quick Setup'!$R46,if(DF3='Quick Setup'!$S$45,'Quick Setup'!$S46,if(DF3='Quick Setup'!$T$45,'Quick Setup'!$T46,if(DF3='Quick Setup'!$U$45,'Quick Setup'!$U46,if(DF3='Quick Setup'!$V$45,'Quick Setup'!$V46,'Quick Setup'!$W46)))))))))))))))))))) -> 1 | DI3: =CW3 -> 5 | DJ3: =CX3 -> -0.05 | DK3: =CY3 -> -0.02 | DL3: =CZ3 -> 0 | DM3: =DA3 -> 0.005 | DN3: =DB3 -> 0.01 | DO3: =DC3 -> 0.015 | DP3: =DD3 -> 0.02 | DQ3: =DE3 -> 0.03 | DR3: ='Quick Setup'!M60 -> 0.775 | DS3: =if(DR3='Quick Setup'!$C$31,'Quick Setup'!$C32,if(DR3='Quick Setup'!$D$31,'Quick Setup'!$D32,if(DR3='Quick Setup'!$E$31,'Quick Setup'!$E32,if(DR3='Quick Setup'!$F$31,'Quick Setup'!$F32,if(DR3='Quick Setup'!$G$31,'Quick Setup'!$G32,if(DR3='Quick Setup'!$H$31,'Quick Setup'!$H32,if(DR3='Quick Setup'!$I$31,'Quick Setup'!$I32,if(DR3='Quick Setup'!$J$31,'Quick Setup'!$J32,if(DR3='Quick Setup'!$K$31,'Quick Setup'!$K32,if(DR3='Quick Setup'!$L$31,'Quick Setup'!$L32,if(DR3='Quick Setup'!$M$31,'Quick Setup'!$M32,if(DR3='Quick Setup'!$N$31,'Quick Setup'!$N32,if(DR3='Quick Setup'!$O$31,'Quick Setup'!$O32,if(DR3='Quick Setup'!$P$31,'Quick Setup'!$P32,if(DR3='Quick Setup'!$Q$31,'Quick Setup'!$Q32,if(DR3='Quick Setup'!$R$31,'Quick Setup'!$R32,if(DR3='Quick Setup'!$S$31,'Quick Setup'!$S32,if(DR3='Quick Setup'!$T$31,'Quick Setup'!$T32,if(DR3='Quick Setup'!$U$31,'Quick Setup'!$U32,if(DR3='Quick Setup'!$V$31,'Quick Setup'!$V32,'Quick Setup'!$W32)))))))))))))))))))) -> 4 | DT3: =if(DR3='Quick Setup'!$C$45,'Quick Setup'!$C46,if(DR3='Quick Setup'!$D$45,'Quick Setup'!$D46,if(DR3='Quick Setup'!$E$45,'Quick Setup'!$E46,if(DR3='Quick Setup'!$F$45,'Quick Setup'!$F46,if(DR3='Quick Setup'!$G$45,'Quick Setup'!$G46,if(DR3='Quick Setup'!$H$45,'Quick Setup'!$H46,if(DR3='Quick Setup'!$I$45,'Quick Setup'!$I46,if(DR3='Quick Setup'!$J$45,'Quick Setup'!$J46,if(DR3='Quick Setup'!$K$45,'Quick Setup'!$K46,if(DR3='Quick Setup'!$L$45,'Quick Setup'!$L46,if(DR3='Quick Setup'!$M$45,'Quick Setup'!$M46,if(DR3='Quick Setup'!$N$45,'Quick Setup'!$N46,if(DR3='Quick Setup'!$O$45,'Quick Setup'!$O46,if(DR3='Quick Setup'!$P$45,'Quick Setup'!$P46,if(DR3='Quick Setup'!$Q$45,'Quick Setup'!$Q46,if(DR3='Quick Setup'!$R$45,'Quick Setup'!$R46,if(DR3='Quick Setup'!$S$45,'Quick Setup'!$S46,if(DR3='Quick Setup'!$T$45,'Quick Setup'!$T46,if(DR3='Quick Setup'!$U$45,'Quick Setup'!$U46,if(DR3='Quick Setup'!$V$45,'Quick Setup'!$V46,'Quick Setup'!$W46)))))))))))))))))))) -> 2 | DU3: =DI3 -> 5 | DV3: =DJ3 -> -0.05 | DW3: =DK3 -> -0.02 | DX3: =DL3 -> 0 | DY3: =DM3 -> 0.005 | DZ3: =DN3 -> 0.01 | EA3: =DO3 -> 0.015 | EB3: =DP3 -> 0.02 | EC3: =DQ3 -> 0.03 | ED3: ='Quick Setup'!N60 -> 0.825 | EE3: =if(ED3='Quick Setup'!$C$31,'Quick Setup'!$C32,if(ED3='Quick Setup'!$D$31,'Quick Setup'!$D32,if(ED3='Quick Setup'!$E$31,'Quick Setup'!$E32,if(ED3='Quick Setup'!$F$31,'Quick Setup'!$F32,if(ED3='Quick Setup'!$G$31,'Quick Setup'!$G32,if(ED3='Quick Setup'!$H$31,'Quick Setup'!$H32,if(ED3='Quick Setup'!$I$31,'Quick Setup'!$I32,if(ED3='Quick Setup'!$J$31,'Quick Setup'!$J32,if(ED3='Quick Setup'!$K$31,'Quick Setup'!$K32,if(ED3='Quick Setup'!$L$31,'Quick Setup'!$L32,if(ED3='Quick Setup'!$M$31,'Quick Setup'!$M32,if(ED3='Quick Setup'!$N$31,'Quick Setup'!$N32,if(ED3='Quick Setup'!$O$31,'Quick Setup'!$O32,if(ED3='Quick Setup'!$P$31,'Quick Setup'!$P32,if(ED3='Quick Setup'!$Q$31,'Quick Setup'!$Q32,if(ED3='Quick Setup'!$R$31,'Quick Setup'!$R32,if(ED3='Quick Setup'!$S$31,'Quick Setup'!$S32,if(ED3='Quick Setup'!$T$31,'Quick Setup'!$T32,if(ED3='Quick Setup'!$U$31,'Quick Setup'!$U32,if(ED3='Quick Setup'!$V$31,'Quick Setup'!$V32,'Quick Setup'!$W32)))))))))))))))))))) -> 3 | EF3: =if(ED3='Quick Setup'!$C$45,'Quick Setup'!$C46,if(ED3='Quick Setup'!$D$45,'Quick Setup'!$D46,if(ED3='Quick Setup'!$E$45,'Quick Setup'!$E46,if(ED3='Quick Setup'!$F$45,'Quick Setup'!$F46,if(ED3='Quick Setup'!$G$45,'Quick Setup'!$G46,if(ED3='Quick Setup'!$H$45,'Quick Setup'!$H46,if(ED3='Quick Setup'!$I$45,'Quick Setup'!$I46,if(ED3='Quick Setup'!$J$45,'Quick Setup'!$J46,if(ED3='Quick Setup'!$K$45,'Quick Setup'!$K46,if(ED3='Quick Setup'!$L$45,'Quick Setup'!$L46,if(ED3='Quick Setup'!$M$45,'Quick Setup'!$M46,if(ED3='Quick Setup'!$N$45,'Quick Setup'!$N46,if(ED3='Quick Setup'!$O$45,'Quick Setup'!$O46,if(ED3='Quick Setup'!$P$45,'Quick Setup'!$P46,if(ED3='Quick Setup'!$Q$45,'Quick Setup'!$Q46,if(ED3='Quick Setup'!$R$45,'Quick Setup'!$R46,if(ED3='Quick Setup'!$S$45,'Quick Setup'!$S46,if(ED3='Quick Setup'!$T$45,'Quick Setup'!$T46,if(ED3='Quick Setup'!$U$45,'Quick Setup'!$U46,if(ED3='Quick Setup'!$V$45,'Quick Setup'!$V46,'Quick Setup'!$W46)))))))))))))))))))) -> 2 | EG3: =DU3 -> 5 | EH3: =DV3 -> -0.05 | EI3: =DW3 -> -0.02 | EJ3: =DX3 -> 0 | EK3: =DY3 -> 0.005 | EL3: =DZ3 -> 0.01 | EM3: =EA3 -> 0.015 | EN3: =EB3 -> 0.02 | EO3: =EC3 -> 0.03 | EP3: ='Quick Setup'!O60 -> 0.875 | EQ3: =if(EP3='Quick Setup'!$C$31,'Quick Setup'!$C32,if(EP3='Quick Setup'!$D$31,'Quick Setup'!$D32,if(EP3='Quick Setup'!$E$31,'Quick Setup'!$E32,if(EP3='Quick Setup'!$F$31,'Quick Setup'!$F32,if(EP3='Quick Setup'!$G$31,'Quick Setup'!$G32,if(EP3='Quick Setup'!$H$31,'Quick Setup'!$H32,if(EP3='Quick Setup'!$I$31,'Quick Setup'!$I32,if(EP3='Quick Setup'!$J$31,'Quick Setup'!$J32,if(EP3='Quick Setup'!$K$31,'Quick Setup'!$K32,if(EP3='Quick Setup'!$L$31,'Quick Setup'!$L32,if(EP3='Quick Setup'!$M$31,'Quick Setup'!$M32,if(EP3='Quick Setup'!$N$31,'Quick Setup'!$N32,if(EP3='Quick Setup'!$O$31,'Quick Setup'!$O32,if(EP3='Quick Setup'!$P$31,'Quick Setup'!$P32,if(EP3='Quick Setup'!$Q$31,'Quick Setup'!$Q32,if(EP3='Quick Setup'!$R$31,'Quick Setup'!$R32,if(EP3='Quick Setup'!$S$31,'Quick Setup'!$S32,if(EP3='Quick Setup'!$T$31,'Quick Setup'!$T32,if(EP3='Quick Setup'!$U$31,'Quick Setup'!$U32,if(EP3='Quick Setup'!$V$31,'Quick Setup'!$V32,'Quick Setup'!$W32)))))))))))))))))))) -> 2 | ER3: =if(EP3='Quick Setup'!$C$45,'Quick Setup'!$C46,if(EP3='Quick Setup'!$D$45,'Quick Setup'!$D46,if(EP3='Quick Setup'!$E$45,'Quick Setup'!$E46,if(EP3='Quick Setup'!$F$45,'Quick Setup'!$F46,if(EP3='Quick Setup'!$G$45,'Quick Setup'!$G46,if(EP3='Quick Setup'!$H$45,'Quick Setup'!$H46,if(EP3='Quick Setup'!$I$45,'Quick Setup'!$I46,if(EP3='Quick Setup'!$J$45,'Quick Setup'!$J46,if(EP3='Quick Setup'!$K$45,'Quick Setup'!$K46,if(EP3='Quick Setup'!$L$45,'Quick Setup'!$L46,if(EP3='Quick Setup'!$M$45,'Quick Setup'!$M46,if(EP3='Quick Setup'!$N$45,'Quick Setup'!$N46,if(EP3='Quick Setup'!$O$45,'Quick Setup'!$O46,if(EP3='Quick Setup'!$P$45,'Quick Setup'!$P46,if(EP3='Quick Setup'!$Q$45,'Quick Setup'!$Q46,if(EP3='Quick Setup'!$R$45,'Quick Setup'!$R46,if(EP3='Quick Setup'!$S$45,'Quick Setup'!$S46,if(EP3='Quick Setup'!$T$45,'Quick Setup'!$T46,if(EP3='Quick Setup'!$U$45,'Quick Setup'!$U46,if(EP3='Quick Setup'!$V$45,'Quick Setup'!$V46,'Quick Setup'!$W46)))))))))))))))))))) -> 1 | ES3: =EG3 -> 5 | ET3: =EH3 -> -0.05 | EU3: =EI3 -> -0.02 | EV3: =EJ3 -> 0 | EW3: =EK3 -> 0.005 | EX3: =EL3 -> 0.01 | EY3: =EM3 -> 0.015 | EZ3: =EN3 -> 0.02 | FA3: =EO3 -> 0.03 | FB3: ='Quick Setup'!P60 -> 0.6 | FC3: =if(FB3='Quick Setup'!$C$31,'Quick Setup'!$C32,if(FB3='Quick Setup'!$D$31,'Quick Setup'!$D32,if(FB3='Quick Setup'!$E$31,'Quick Setup'!$E32,if(FB3='Quick Setup'!$F$31,'Quick Setup'!$F32,if(FB3='Quick Setup'!$G$31,'Quick Setup'!$G32,if(FB3='Quick Setup'!$H$31,'Quick Setup'!$H32,if(FB3='Quick Setup'!$I$31,'Quick Setup'!$I32,if(FB3='Quick Setup'!$J$31,'Quick Setup'!$J32,if(FB3='Quick Setup'!$K$31,'Quick Setup'!$K32,if(FB3='Quick Setup'!$L$31,'Quick Setup'!$L32,if(FB3='Quick Setup'!$M$31,'Quick Setup'!$M32,if(FB3='Quick Setup'!$N$31,'Quick Setup'!$N32,if(FB3='Quick Setup'!$O$31,'Quick Setup'!$O32,if(FB3='Quick Setup'!$P$31,'Quick Setup'!$P32,if(FB3='Quick Setup'!$Q$31,'Quick Setup'!$Q32,if(FB3='Quick Setup'!$R$31,'Quick Setup'!$R32,if(FB3='Quick Setup'!$S$31,'Quick Setup'!$S32,if(FB3='Quick Setup'!$T$31,'Quick Setup'!$T32,if(FB3='Quick Setup'!$U$31,'Quick Setup'!$U32,if(FB3='Quick Setup'!$V$31,'Quick Setup'!$V32,'Quick Setup'!$W32)))))))))))))))))))) -> 7 | FD3: =if(FB3='Quick Setup'!$C$45,'Quick Setup'!$C46,if(FB3='Quick Setup'!$D$45,'Quick Setup'!$D46,if(FB3='Quick Setup'!$E$45,'Quick Setup'!$E46,if(FB3='Quick Setup'!$F$45,'Quick Setup'!$F46,if(FB3='Quick Setup'!$G$45,'Quick Setup'!$G46,if(FB3='Quick Setup'!$H$45,'Quick Setup'!$H46,if(FB3='Quick Setup'!$I$45,'Quick Setup'!$I46,if(FB3='Quick Setup'!$J$45,'Quick Setup'!$J46,if(FB3='Quick Setup'!$K$45,'Quick Setup'!$K46,if(FB3='Quick Setup'!$L$45,'Quick Setup'!$L46,if(FB3='Quick Setup'!$M$45,'Quick Setup'!$M46,if(FB3='Quick Setup'!$N$45,'Quick Setup'!$N46,if(FB3='Quick Setup'!$O$45,'Quick Setup'!$O46,if(FB3='Quick Setup'!$P$45,'Quick Setup'!$P46,if(FB3='Quick Setup'!$Q$45,'Quick Setup'!$Q46,if(FB3='Quick Setup'!$R$45,'Quick Setup'!$R46,if(FB3='Quick Setup'!$S$45,'Quick Setup'!$S46,if(FB3='Quick Setup'!$T$45,'Quick Setup'!$T46,if(FB3='Quick Setup'!$U$45,'Quick Setup'!$U46,if(FB3='Quick Setup'!$V$45,'Quick Setup'!$V46,'Quick Setup'!$W46)))))))))))))))))))) -> 3 | FE3: =ES3 -> 5 | FF3: =ET3 -> -0.05 | FG3: =EU3 -> -0.02 | FH3: =EV3 -> 0 | FI3: =EW3 -> 0.005 | FJ3: =EX3 -> 0.01 | FK3: =EY3 -> 0.015 | FL3: =EZ3 -> 0.02 | FM3: =FA3 -> 0.03 | FN3: ='Quick Setup'!Q60 -> 0.8 | FO3: =if(FN3='Quick Setup'!$C$31,'Quick Setup'!$C32,if(FN3='Quick Setup'!$D$31,'Quick Setup'!$D32,if(FN3='Quick Setup'!$E$31,'Quick Setup'!$E32,if(FN3='Quick Setup'!$F$31,'Quick Setup'!$F32,if(FN3='Quick Setup'!$G$31,'Quick Setup'!$G32,if(FN3='Quick Setup'!$H$31,'Quick Setup'!$H32,if(FN3='Quick Setup'!$I$31,'Quick Setup'!$I32,if(FN3='Quick Setup'!$J$31,'Quick Setup'!$J32,if(FN3='Quick Setup'!$K$31,'Quick Setup'!$K32,if(FN3='Quick Setup'!$L$31,'Quick Setup'!$L32,if(FN3='Quick Setup'!$M$31,'Quick Setup'!$M32,if(FN3='Quick Setup'!$N$31,'Quick Setup'!$N32,if(FN3='Quick Setup'!$O$31,'Quick Setup'!$O32,if(FN3='Quick Setup'!$P$31,'Quick Setup'!$P32,if(FN3='Quick Setup'!$Q$31,'Quick Setup'!$Q32,if(FN3='Quick Setup'!$R$31,'Quick Setup'!$R32,if(FN3='Quick Setup'!$S$31,'Quick Setup'!$S32,if(FN3='Quick Setup'!$T$31,'Quick Setup'!$T32,if(FN3='Quick Setup'!$U$31,'Quick Setup'!$U32,if(FN3='Quick Setup'!$V$31,'Quick Setup'!$V32,'Quick Setup'!$W32)))))))))))))))))))) -> 3 | FP3: =if(FN3='Quick Setup'!$C$45,'Quick Setup'!$C46,if(FN3='Quick Setup'!$D$45,'Quick Setup'!$D46,if(FN3='Quick Setup'!$E$45,'Quick Setup'!$E46,if(FN3='Quick Setup'!$F$45,'Quick Setup'!$F46,if(FN3='Quick Setup'!$G$45,'Quick Setup'!$G46,if(FN3='Quick Setup'!$H$45,'Quick Setup'!$H46,if(FN3='Quick Setup'!$I$45,'Quick Setup'!$I46,if(FN3='Quick Setup'!$J$45,'Quick Setup'!$J46,if(FN3='Quick Setup'!$K$45,'Quick Setup'!$K46,if(FN3='Quick Setup'!$L$45,'Quick Setup'!$L46,if(FN3='Quick Setup'!$M$45,'Quick Setup'!$M46,if(FN3='Quick Setup'!$N$45,'Quick Setup'!$N46,if(FN3='Quick Setup'!$O$45,'Quick Setup'!$O46,if(FN3='Quick Setup'!$P$45,'Quick Setup'!$P46,if(FN3='Quick Setup'!$Q$45,'Quick Setup'!$Q46,if(FN3='Quick Setup'!$R$45,'Quick Setup'!$R46,if(FN3='Quick Setup'!$S$45,'Quick Setup'!$S46,if(FN3='Quick Setup'!$T$45,'Quick Setup'!$T46,if(FN3='Quick Setup'!$U$45,'Quick Setup'!$U46,if(FN3='Quick Setup'!$V$45,'Quick Setup'!$V46,'Quick Setup'!$W46)))))))))))))))))))) -> 2 | FQ3: =FE3 -> 5 | FR3: =FF3 -> -0.05 | FS3: =FG3 -> -0.02 | FT3: =FH3 -> 0 | FU3: =FI3 -> 0.005 | FV3: =FJ3 -> 0.01 | FW3: =FK3 -> 0.015 | FX3: =FL3 -> 0.02 | FY3: =FM3 -> 0.03 | FZ3: ='Quick Setup'!R60 -> 0.85 | GA3: =if(FZ3='Quick Setup'!$C$31,'Quick Setup'!$C32,if(FZ3='Quick Setup'!$D$31,'Quick Setup'!$D32,if(FZ3='Quick Setup'!$E$31,'Quick Setup'!$E32,if(FZ3='Quick Setup'!$F$31,'Quick Setup'!$F32,if(FZ3='Quick Setup'!$G$31,'Quick Setup'!$G32,if(FZ3='Quick Setup'!$H$31,'Quick Setup'!$H32,if(FZ3='Quick Setup'!$I$31,'Quick Setup'!$I32,if(FZ3='Quick Setup'!$J$31,'Quick Setup'!$J32,if(FZ3='Quick Setup'!$K$31,'Quick Setup'!$K32,if(FZ3='Quick Setup'!$L$31,'Quick Setup'!$L32,if(FZ3='Quick Setup'!$M$31,'Quick Setup'!$M32,if(FZ3='Quick Setup'!$N$31,'Quick Setup'!$N32,if(FZ3='Quick Setup'!$O$31,'Quick Setup'!$O32,if(FZ3='Quick Setup'!$P$31,'Quick Setup'!$P32,if(FZ3='Quick Setup'!$Q$31,'Quick Setup'!$Q32,if(FZ3='Quick Setup'!$R$31,'Quick Setup'!$R32,if(FZ3='Quick Setup'!$S$31,'Quick Setup'!$S32,if(FZ3='Quick Setup'!$T$31,'Quick Setup'!$T32,if(FZ3='Quick Setup'!$U$31,'Quick Setup'!$U32,if(FZ3='Quick Setup'!$V$31,'Quick Setup'!$V32,'Quick Setup'!$W32)))))))))))))))))))) -> 2 | GB3: =if(FZ3='Quick Setup'!$C$45,'Quick Setup'!$C46,if(FZ3='Quick Setup'!$D$45,'Quick Setup'!$D46,if(FZ3='Quick Setup'!$E$45,'Quick Setup'!$E46,if(FZ3='Quick Setup'!$F$45,'Quick Setup'!$F46,if(FZ3='Quick Setup'!$G$45,'Quick Setup'!$G46,if(FZ3='Quick Setup'!$H$45,'Quick Setup'!$H46,if(FZ3='Quick Setup'!$I$45,'Quick Setup'!$I46,if(FZ3='Quick Setup'!$J$45,'Quick Setup'!$J46,if(FZ3='Quick Setup'!$K$45,'Quick Setup'!$K46,if(FZ3='Quick Setup'!$L$45,'Quick Setup'!$L46,if(FZ3='Quick Setup'!$M$45,'Quick Setup'!$M46,if(FZ3='Quick Setup'!$N$45,'Quick Setup'!$N46,if(FZ3='Quick Setup'!$O$45,'Quick Setup'!$O46,if(FZ3='Quick Setup'!$P$45,'Quick Setup'!$P46,if(FZ3='Quick Setup'!$Q$45,'Quick Setup'!$Q46,if(FZ3='Quick Setup'!$R$45,'Quick Setup'!$R46,if(FZ3='Quick Setup'!$S$45,'Quick Setup'!$S46,if(FZ3='Quick Setup'!$T$45,'Quick Setup'!$T46,if(FZ3='Quick Setup'!$U$45,'Quick Setup'!$U46,if(FZ3='Quick Setup'!$V$45,'Quick Setup'!$V46,'Quick Setup'!$W46)))))))))))))))))))) -> 1 | GC3: =FQ3 -> 5 | GD3: =FR3 -> -0.05 | GE3: =FS3 -> -0.02 | GF3: =FT3 -> 0 | GG3: =FU3 -> 0.005 | GH3: =FV3 -> 0.01 | GI3: =FW3 -> 0.015 | GJ3: =FX3 -> 0.02 | GK3: =FY3 -> 0.03 | GL3: ='Quick Setup'!S60 -> 0.9 | GM3: =if(GL3='Quick Setup'!$C$31,'Quick Setup'!$C32,if(GL3='Quick Setup'!$D$31,'Quick Setup'!$D32,if(GL3='Quick Setup'!$E$31,'Quick Setup'!$E32,if(GL3='Quick Setup'!$F$31,'Quick Setup'!$F32,if(GL3='Quick Setup'!$G$31,'Quick Setup'!$G32,if(GL3='Quick Setup'!$H$31,'Quick Setup'!$H32,if(GL3='Quick Setup'!$I$31,'Quick Setup'!$I32,if(GL3='Quick Setup'!$J$31,'Quick Setup'!$J32,if(GL3='Quick Setup'!$K$31,'Quick Setup'!$K32,if(GL3='Quick Setup'!$L$31,'Quick Setup'!$L32,if(GL3='Quick Setup'!$M$31,'Quick Setup'!$M32,if(GL3='Quick Setup'!$N$31,'Quick Setup'!$N32,if(GL3='Quick Setup'!$O$31,'Quick Setup'!$O32,if(GL3='Quick Setup'!$P$31,'Quick Setup'!$P32,if(GL3='Quick Setup'!$Q$31,'Quick Setup'!$Q32,if(GL3='Quick Setup'!$R$31,'Quick Setup'!$R32,if(GL3='Quick Setup'!$S$31,'Quick Setup'!$S32,if(GL3='Quick Setup'!$T$31,'Quick Setup'!$T32,if(GL3='Quick Setup'!$U$31,'Quick Setup'!$U32,if(GL3='Quick Setup'!$V$31,'Quick Setup'!$V32,'Quick Setup'!$W32)))))))))))))))))))) -> 1 | GN3: =if(GL3='Quick Setup'!$C$45,'Quick Setup'!$C46,if(GL3='Quick Setup'!$D$45,'Quick Setup'!$D46,if(GL3='Quick Setup'!$E$45,'Quick Setup'!$E46,if(GL3='Quick Setup'!$F$45,'Quick Setup'!$F46,if(GL3='Quick Setup'!$G$45,'Quick Setup'!$G46,if(GL3='Quick Setup'!$H$45,'Quick Setup'!$H46,if(GL3='Quick Setup'!$I$45,'Quick Setup'!$I46,if(GL3='Quick Setup'!$J$45,'Quick Setup'!$J46,if(GL3='Quick Setup'!$K$45,'Quick Setup'!$K46,if(GL3='Quick Setup'!$L$45,'Quick Setup'!$L46,if(GL3='Quick Setup'!$M$45,'Quick Setup'!$M46,if(GL3='Quick Setup'!$N$45,'Quick Setup'!$N46,if(GL3='Quick Setup'!$O$45,'Quick Setup'!$O46,if(GL3='Quick Setup'!$P$45,'Quick Setup'!$P46,if(GL3='Quick Setup'!$Q$45,'Quick Setup'!$Q46,if(GL3='Quick Setup'!$R$45,'Quick Setup'!$R46,if(GL3='Quick Setup'!$S$45,'Quick Setup'!$S46,if(GL3='Quick Setup'!$T$45,'Quick Setup'!$T46,if(GL3='Quick Setup'!$U$45,'Quick Setup'!$U46,if(GL3='Quick Setup'!$V$45,'Quick Setup'!$V46,'Quick Setup'!$W46)))))))))))))))))))) -> 1 | GO3: =GC3 -> 5 | GP3: =GD3 -> -0.05 | GQ3: =GE3 -> -0.02 | GR3: =GF3 -> 0 | GS3: =GG3 -> 0.005 | GT3: =GH3 -> 0.01 | GU3: =GI3 -> 0.015 | GV3: =GJ3 -> 0.02 | GW3: =GK3 -> 0.03 | GX3: ='Quick Setup'!T60 -> 0.85 | GY3: =if(GX3='Quick Setup'!$C$31,'Quick Setup'!$C32,if(GX3='Quick Setup'!$D$31,'Quick Setup'!$D32,if(GX3='Quick Setup'!$E$31,'Quick Setup'!$E32,if(GX3='Quick Setup'!$F$31,'Quick Setup'!$F32,if(GX3='Quick Setup'!$G$31,'Quick Setup'!$G32,if(GX3='Quick Setup'!$H$31,'Quick Setup'!$H32,if(GX3='Quick Setup'!$I$31,'Quick Setup'!$I32,if(GX3='Quick Setup'!$J$31,'Quick Setup'!$J32,if(GX3='Quick Setup'!$K$31,'Quick Setup'!$K32,if(GX3='Quick Setup'!$L$31,'Quick Setup'!$L32,if(GX3='Quick Setup'!$M$31,'Quick Setup'!$M32,if(GX3='Quick Setup'!$N$31,'Quick Setup'!$N32,if(GX3='Quick Setup'!$O$31,'Quick Setup'!$O32,if(GX3='Quick Setup'!$P$31,'Quick Setup'!$P32,if(GX3='Quick Setup'!$Q$31,'Quick Setup'!$Q32,if(GX3='Quick Setup'!$R$31,'Quick Setup'!$R32,if(GX3='Quick Setup'!$S$31,'Quick Setup'!$S32,if(GX3='Quick Setup'!$T$31,'Quick Setup'!$T32,if(GX3='Quick Setup'!$U$31,'Quick Setup'!$U32,if(GX3='Quick Setup'!$V$31,'Quick Setup'!$V32,'Quick Setup'!$W32)))))))))))))))))))) -> 2 | GZ3: =if(GX3='Quick Setup'!$C$45,'Quick Setup'!$C46,if(GX3='Quick Setup'!$D$45,'Quick Setup'!$D46,if(GX3='Quick Setup'!$E$45,'Quick Setup'!$E46,if(GX3='Quick Setup'!$F$45,'Quick Setup'!$F46,if(GX3='Quick Setup'!$G$45,'Quick Setup'!$G46,if(GX3='Quick Setup'!$H$45,'Quick Setup'!$H46,if(GX3='Quick Setup'!$I$45,'Quick Setup'!$I46,if(GX3='Quick Setup'!$J$45,'Quick Setup'!$J46,if(GX3='Quick Setup'!$K$45,'Quick Setup'!$K46,if(GX3='Quick Setup'!$L$45,'Quick Setup'!$L46,if(GX3='Quick Setup'!$M$45,'Quick Setup'!$M46,if(GX3='Quick Setup'!$N$45,'Quick Setup'!$N46,if(GX3='Quick Setup'!$O$45,'Quick Setup'!$O46,if(GX3='Quick Setup'!$P$45,'Quick Setup'!$P46,if(GX3='Quick Setup'!$Q$45,'Quick Setup'!$Q46,if(GX3='Quick Setup'!$R$45,'Quick Setup'!$R46,if(GX3='Quick Setup'!$S$45,'Quick Setup'!$S46,if(GX3='Quick Setup'!$T$45,'Quick Setup'!$T46,if(GX3='Quick Setup'!$U$45,'Quick Setup'!$U46,if(GX3='Quick Setup'!$V$45,'Quick Setup'!$V46,'Quick Setup'!$W46)))))))))))))))))))) -> 1 | HA3: =GO3 -> 5 | HB3: =GP3 -> -0.05 | HC3: =GQ3 -> -0.02 | HD3: =GR3 -> 0 | HE3: =GS3 -> 0.005 | HF3: =GT3 -> 0.01 | HG3: =GU3 -> 0.015 | HH3: =GV3 -> 0.02 | HI3: =GW3 -> 0.03 | HJ3: ='Quick Setup'!U60 -> 0.9 | HK3: =if(HJ3='Quick Setup'!$C$31,'Quick Setup'!$C32,if(HJ3='Quick Setup'!$D$31,'Quick Setup'!$D32,if(HJ3='Quick Setup'!$E$31,'Quick Setup'!$E32,if(HJ3='Quick Setup'!$F$31,'Quick Setup'!$F32,if(HJ3='Quick Setup'!$G$31,'Quick Setup'!$G32,if(HJ3='Quick Setup'!$H$31,'Quick Setup'!$H32,if(HJ3='Quick Setup'!$I$31,'Quick Setup'!$I32,if(HJ3='Quick Setup'!$J$31,'Quick Setup'!$J32,if(HJ3='Quick Setup'!$K$31,'Quick Setup'!$K32,if(HJ3='Quick Setup'!$L$31,'Quick Setup'!$L32,if(HJ3='Quick Setup'!$M$31,'Quick Setup'!$M32,if(HJ3='Quick Setup'!$N$31,'Quick Setup'!$N32,if(HJ3='Quick Setup'!$O$31,'Quick Setup'!$O32,if(HJ3='Quick Setup'!$P$31,'Quick Setup'!$P32,if(HJ3='Quick Setup'!$Q$31,'Quick Setup'!$Q32,if(HJ3='Quick Setup'!$R$31,'Quick Setup'!$R32,if(HJ3='Quick Setup'!$S$31,'Quick Setup'!$S32,if(HJ3='Quick Setup'!$T$31,'Quick Setup'!$T32,if(HJ3='Quick Setup'!$U$31,'Quick Setup'!$U32,if(HJ3='Quick Setup'!$V$31,'Quick Setup'!$V32,'Quick Setup'!$W32)))))))))))))))))))) -> 1 | HL3: =if(HJ3='Quick Setup'!$C$45,'Quick Setup'!$C46,if(HJ3='Quick Setup'!$D$45,'Quick Setup'!$D46,if(HJ3='Quick Setup'!$E$45,'Quick Setup'!$E46,if(HJ3='Quick Setup'!$F$45,'Quick Setup'!$F46,if(HJ3='Quick Setup'!$G$45,'Quick Setup'!$G46,if(HJ3='Quick Setup'!$H$45,'Quick Setup'!$H46,if(HJ3='Quick Setup'!$I$45,'Quick Setup'!$I46,if(HJ3='Quick Setup'!$J$45,'Quick Setup'!$J46,if(HJ3='Quick Setup'!$K$45,'Quick Setup'!$K46,if(HJ3='Quick Setup'!$L$45,'Quick Setup'!$L46,if(HJ3='Quick Setup'!$M$45,'Quick Setup'!$M46,if(HJ3='Quick Setup'!$N$45,'Quick Setup'!$N46,if(HJ3='Quick Setup'!$O$45,'Quick Setup'!$O46,if(HJ3='Quick Setup'!$P$45,'Quick Setup'!$P46,if(HJ3='Quick Setup'!$Q$45,'Quick Setup'!$Q46,if(HJ3='Quick Setup'!$R$45,'Quick Setup'!$R46,if(HJ3='Quick Setup'!$S$45,'Quick Setup'!$S46,if(HJ3='Quick Setup'!$T$45,'Quick Setup'!$T46,if(HJ3='Quick Setup'!$U$45,'Quick Setup'!$U46,if(HJ3='Quick Setup'!$V$45,'Quick Setup'!$V46,'Quick Setup'!$W46)))))))))))))))))))) -> 1 | HM3: =HA3 -> 5 | HN3: =HB3 -> -0.05 | HO3: =HC3 -> -0.02 | HP3: =HD3 -> 0 | HQ3: =HE3 -> 0.005 | HR3: =HF3 -> 0.01 | HS3: =HG3 -> 0.015 | HT3: =HH3 -> 0.02 | HU3: =HI3 -> 0.03 | HV3: ='Quick Setup'!V60 -> 0.95 | HW3: =if(HV3='Quick Setup'!$C$31,'Quick Setup'!$C32,if(HV3='Quick Setup'!$D$31,'Quick Setup'!$D32,if(HV3='Quick Setup'!$E$31,'Quick Setup'!$E32,if(HV3='Quick Setup'!$F$31,'Quick Setup'!$F32,if(HV3='Quick Setup'!$G$31,'Quick Setup'!$G32,if(HV3='Quick Setup'!$H$31,'Quick Setup'!$H32,if(HV3='Quick Setup'!$I$31,'Quick Setup'!$I32,if(HV3='Quick Setup'!$J$31,'Quick Setup'!$J32,if(HV3='Quick Setup'!$K$31,'Quick Setup'!$K32,if(HV3='Quick Setup'!$L$31,'Quick Setup'!$L32,if(HV3='Quick Setup'!$M$31,'Quick Setup'!$M32,if(HV3='Quick Setup'!$N$31,'Quick Setup'!$N32,if(HV3='Quick Setup'!$O$31,'Quick Setup'!$O32,if(HV3='Quick Setup'!$P$31,'Quick Setup'!$P32,if(HV3='Quick Setup'!$Q$31,'Quick Setup'!$Q32,if(HV3='Quick Setup'!$R$31,'Quick Setup'!$R32,if(HV3='Quick Setup'!$S$31,'Quick Setup'!$S32,if(HV3='Quick Setup'!$T$31,'Quick Setup'!$T32,if(HV3='Quick Setup'!$U$31,'Quick Setup'!$U32,if(HV3='Quick Setup'!$V$31,'Quick Setup'!$V32,'Quick Setup'!$W32)))))))))))))))))))) -> 1 | HX3: =if(HV3='Quick Setup'!$C$45,'Quick Setup'!$C46,if(HV3='Quick Setup'!$D$45,'Quick Setup'!$D46,if(HV3='Quick Setup'!$E$45,'Quick Setup'!$E46,if(HV3='Quick Setup'!$F$45,'Quick Setup'!$F46,if(HV3='Quick Setup'!$G$45,'Quick Setup'!$G46,if(HV3='Quick Setup'!$H$45,'Quick Setup'!$H46,if(HV3='Quick Setup'!$I$45,'Quick Setup'!$I46,if(HV3='Quick Setup'!$J$45,'Quick Setup'!$J46,if(HV3='Quick Setup'!$K$45,'Quick Setup'!$K46,if(HV3='Quick Setup'!$L$45,'Quick Setup'!$L46,if(HV3='Quick Setup'!$M$45,'Quick Setup'!$M46,if(HV3='Quick Setup'!$N$45,'Quick Setup'!$N46,if(HV3='Quick Setup'!$O$45,'Quick Setup'!$O46,if(HV3='Quick Setup'!$P$45,'Quick Setup'!$P46,if(HV3='Quick Setup'!$Q$45,'Quick Setup'!$Q46,if(HV3='Quick Setup'!$R$45,'Quick Setup'!$R46,if(HV3='Quick Setup'!$S$45,'Quick Setup'!$S46,if(HV3='Quick Setup'!$T$45,'Quick Setup'!$T46,if(HV3='Quick Setup'!$U$45,'Quick Setup'!$U46,if(HV3='Quick Setup'!$V$45,'Quick Setup'!$V46,'Quick Setup'!$W46)))))))))))))))))))) -> 1 | HY3: =HM3 -> 5 | HZ3: =HN3 -> -0.05 | IA3: =HO3 -> -0.02 | IB3: =HP3 -> 0 | IC3: =HQ3 -> 0.005 | ID3: =HR3 -> 0.01 | IE3: =HS3 -> 0.015 | IF3: =HT3 -> 0.02 | IG3: =HU3 -> 0.03 | IH3: ='Quick Setup'!W60 -> 0.6 | II3: =if(IH3='Quick Setup'!$C$31,'Quick Setup'!$C32,if(IH3='Quick Setup'!$D$31,'Quick Setup'!$D32,if(IH3='Quick Setup'!$E$31,'Quick Setup'!$E32,if(IH3='Quick Setup'!$F$31,'Quick Setup'!$F32,if(IH3='Quick Setup'!$G$31,'Quick Setup'!$G32,if(IH3='Quick Setup'!$H$31,'Quick Setup'!$H32,if(IH3='Quick Setup'!$I$31,'Quick Setup'!$I32,if(IH3='Quick Setup'!$J$31,'Quick Setup'!$J32,if(IH3='Quick Setup'!$K$31,'Quick Setup'!$K32,if(IH3='Quick Setup'!$L$31,'Quick Setup'!$L32,if(IH3='Quick Setup'!$M$31,'Quick Setup'!$M32,if(IH3='Quick Setup'!$N$31,'Quick Setup'!$N32,if(IH3='Quick Setup'!$O$31,'Quick Setup'!$O32,if(IH3='Quick Setup'!$P$31,'Quick Setup'!$P32,if(IH3='Quick Setup'!$Q$31,'Quick Setup'!$Q32,if(IH3='Quick Setup'!$R$31,'Quick Setup'!$R32,if(IH3='Quick Setup'!$S$31,'Quick Setup'!$S32,if(IH3='Quick Setup'!$T$31,'Quick Setup'!$T32,if(IH3='Quick Setup'!$U$31,'Quick Setup'!$U32,if(IH3='Quick Setup'!$V$31,'Quick Setup'!$V32,'Quick Setup'!$W32)))))))))))))))))))) -> 7 | IJ3: =if(IH3='Quick Setup'!$C$45,'Quick Setup'!$C46,if(IH3='Quick Setup'!$D$45,'Quick Setup'!$D46,if(IH3='Quick Setup'!$E$45,'Quick Setup'!$E46,if(IH3='Quick Setup'!$F$45,'Quick Setup'!$F46,if(IH3='Quick Setup'!$G$45,'Quick Setup'!$G46,if(IH3='Quick Setup'!$H$45,'Quick Setup'!$H46,if(IH3='Quick Setup'!$I$45,'Quick Setup'!$I46,if(IH3='Quick Setup'!$J$45,'Quick Setup'!$J46,if(IH3='Quick Setup'!$K$45,'Quick Setup'!$K46,if(IH3='Quick Setup'!$L$45,'Quick Setup'!$L46,if(IH3='Quick Setup'!$M$45,'Quick Setup'!$M46,if(IH3='Quick Setup'!$N$45,'Quick Setup'!$N46,if(IH3='Quick Setup'!$O$45,'Quick Setup'!$O46,if(IH3='Quick Setup'!$P$45,'Quick Setup'!$P46,if(IH3='Quick Setup'!$Q$45,'Quick Setup'!$Q46,if(IH3='Quick Setup'!$R$45,'Quick Setup'!$R46,if(IH3='Quick Setup'!$S$45,'Quick Setup'!$S46,if(IH3='Quick Setup'!$T$45,'Quick Setup'!$T46,if(IH3='Quick Setup'!$U$45,'Quick Setup'!$U46,if(IH3='Quick Setup'!$V$45,'Quick Setup'!$V46,'Quick Setup'!$W46)))))))))))))))))))) -> 3 | IK3: =HY3 -> 5 | IL3: =HZ3 -> -0.05 | IM3: =IA3 -> -0.02 | IN3: =IB3 -> 0 | IO3: =IC3 -> 0.005 | IP3: =ID3 -> 0.01 | IQ3: =IE3 -> 0.015 | IR3: =IF3 -> 0.02 | IS3: =IG3 -> 0.03
